<?xml version="1.0"?>
<robot name="MELEW3">

  <link name="BODY">
    <inertial>
      <mass value="1.0" />
      <origin xyz="0 0 0.41" rpy="0 0 0" />
      <inertia ixx="0.002083333" ixy="0.0" ixz="0.0" iyy="0.000416667" iyz="0.0" izz="0.002083333" />
    </inertial>
    <visual>
      <geometry>
        <mesh filename="package://MELEW3_description/urdf/MELEW3_stl/body.STL"/>
      </geometry>
    </visual>
    <collision>
      <geometry>
        <mesh filename="package://MELEW3_description/urdf/MELEW3_stl/body.STL"/>
      </geometry>
    </collision>
  </link>

  <link name="HIP_L">
    <inertial>
      <mass value="1.5" />
      <origin xyz="0 0.125 0" rpy="0 0 0" />
      <inertia ixx="0.0015" ixy="0.0" ixz="0.0" iyy="0.0015" iyz="0.0" izz="0.0015" />
    </inertial>
    <visual>
      <geometry>
        <mesh filename="package://MELEW3_description/urdf/MELEW3_stl/hip.STL"/>
      </geometry>
    </visual>
    <collision>
      <geometry>
        <mesh filename="package://MELEW3_description/urdf/MELEW3_stl/hip.STL"/>
      </geometry>
    </collision>  
  </link>

  <link name="HIP_YAW_L">
    <inertial>
      <mass value="0.5" />
      <origin xyz="0 0 0" rpy="0 0 0" />
      <inertia ixx="0.000416667" ixy="0.0" ixz="0.0" iyy="0.000416667" iyz="0.0" izz="0.000625" />
    </inertial>
    <visual>
      <geometry>
        <mesh filename="package://MELEW3_description/urdf/MELEW3_stl/hip_Y.STL"/>
      </geometry>
    </visual>
    <collision>
      <geometry>
        <mesh filename="package://MELEW3_description/urdf/MELEW3_stl/hip_Y.STL"/>
      </geometry>
    </collision>  
  </link>

  <link name="HIP_ROLL_L">
    <inertial>
      <mass value="0.5" />
      <origin xyz="0 0 0" rpy="0 0 0" />
      <inertia ixx="0.000625" ixy="0.0" ixz="0.0" iyy="0.000416667" iyz="0.0" izz="0.000416667" />
    </inertial>
    <visual>
      <geometry>
        <mesh filename="package://MELEW3_description/urdf/MELEW3_stl/hip_R.STL"/>
      </geometry>
    </visual>
    <collision>
      <geometry>
        <mesh filename="package://MELEW3_description/urdf/MELEW3_stl/hip_R.STL"/>
      </geometry>
    </collision>  
  </link>

  <link name="HIP_PITCH_L">
    <inertial>
      <mass value="0.5" />
      <origin xyz="0 0 0" rpy="0 0 0" />
      <inertia ixx="0.000416667" ixy="0.0" ixz="0.0" iyy="0.000625" iyz="0.0" izz="0.000416667" />
    </inertial>
    <visual>
      <geometry>
        <mesh filename="package://MELEW3_description/urdf/MELEW3_stl/hip_P.STL"/>
      </geometry>
    </visual>
    <collision>
      <geometry>
        <mesh filename="package://MELEW3_description/urdf/MELEW3_stl/hip_P.STL"/>
      </geometry>
    </collision> 
  </link>

  <link name="THIGH_L">
    <inertial>
      <mass value="1.2" />
      <origin xyz="0 0 -0.065" rpy="0 0 0" />
      <inertia ixx="0.00692" ixy="0.0" ixz="0.0" iyy="0.00692" iyz="0.0" izz="0.00032" />
    </inertial>
    <visual>
      <geometry>
        <mesh filename="package://MELEW3_description/urdf/MELEW3_stl/thigh.STL"/>
      </geometry>
    </visual>
    <collision>
      <geometry>
        <mesh filename="package://MELEW3_description/urdf/MELEW3_stl/thigh.STL"/>
      </geometry>
    </collision> 
  </link>

  <link name="KNEE_L">
    <inertial>
      <mass value="0.15" />
      <origin xyz="0 0 -0.15" rpy="0 0 0" />
      <inertia ixx="0.000035" ixy="0.0" ixz="0.0" iyy="0.00003" iyz="0.0" izz="0.000035" />
    </inertial>
    <visual>
      <geometry>
        <mesh filename="package://MELEW3_description/urdf/MELEW3_stl/knee.STL"/>
      </geometry>
    </visual>
    <collision>
      <geometry>
        <mesh filename="package://MELEW3_description/urdf/MELEW3_stl/knee.STL"/>
      </geometry>
    </collision> 
  </link>

  <link name="SHIN_L">
    <inertial>
      <mass value="0.6" />
      <origin xyz="0 0 -0.02" rpy="0 0 0" />
      <inertia ixx="0.00581125" ixy="0.0" ixz="0.0" iyy="0.00581125" iyz="0.0" izz="0.0000625" />
    </inertial>
    <visual>
      <geometry>
        <mesh filename="package://MELEW3_description/urdf/MELEW3_stl/shin.STL"/>
      </geometry>
    </visual>
    <collision>
      <geometry>
        <mesh filename="package://MELEW3_description/urdf/MELEW3_stl/shin.STL"/>
      </geometry>
    </collision> 
  </link>

  <link name="FOOT_L">
    <inertial>
      <mass value="0.05" />
      <origin xyz="0 0 -0.18" rpy="0 0 0" />
      <inertia ixx="0.000002" ixy="0.0" ixz="0.0" iyy="0.000002" iyz="0.0" izz="0.000002" />
    </inertial>
    <visual>
      <geometry>
        <mesh filename="package://MELEW3_description/urdf/MELEW3_stl/foot.STL"/>
      </geometry>
    </visual>
    <collision>
      <geometry>
        <mesh filename="package://MELEW3_description/urdf/MELEW3_stl/foot.STL"/>
      </geometry>
    </collision> 
  </link>

  <link name="HIP_R">
    <inertial>
      <mass value="1.5" />
      <origin xyz="0 -0.125 0" rpy="0 0 0" />
      <inertia ixx="0.0015" ixy="0.0" ixz="0.0" iyy="0.0015" iyz="0.0" izz="0.0015" />
    </inertial>
    <visual>
      <geometry>
        <mesh filename="package://MELEW3_description/urdf/MELEW3_stl/hip.STL"/>
      </geometry>
    </visual>
    <collision>
      <geometry>
        <mesh filename="package://MELEW3_description/urdf/MELEW3_stl/hip.STL"/>
      </geometry>
    </collision>  
  </link>

  <link name="HIP_YAW_R">
    <inertial>
      <mass value="0.5" />
      <origin xyz="0 0 0" rpy="0 0 0" />
      <inertia ixx="0.000416667" ixy="0.0" ixz="0.0" iyy="0.000416667" iyz="0.0" izz="0.000625" />
    </inertial>
    <visual>
      <geometry>
        <mesh filename="package://MELEW3_description/urdf/MELEW3_stl/hip_Y.STL"/>
      </geometry>
    </visual>
    <collision>
      <geometry>
        <mesh filename="package://MELEW3_description/urdf/MELEW3_stl/hip_Y.STL"/>
      </geometry>
    </collision>  
  </link>

  <link name="HIP_ROLL_R">
    <inertial>
      <mass value="0.5" />
      <origin xyz="0 0 0" rpy="0 0 0" />
      <inertia ixx="0.000625" ixy="0.0" ixz="0.0" iyy="0.000416667" iyz="0.0" izz="0.000416667" />
    </inertial>
    <visual>
      <geometry>
        <mesh filename="package://MELEW3_description/urdf/MELEW3_stl/hip_R.STL"/>
      </geometry>
    </visual>
    <collision>
      <geometry>
        <mesh filename="package://MELEW3_description/urdf/MELEW3_stl/hip_R.STL"/>
      </geometry>
    </collision>  
  </link>

  <link name="HIP_PITCH_R">
    <inertial>
      <mass value="0.5" />
      <origin xyz="0 0 0" rpy="0 0 0" />
      <inertia ixx="0.000416667" ixy="0.0" ixz="0.0" iyy="0.000625" iyz="0.0" izz="0.000416667" />
    </inertial>
    <visual>
      <geometry>
        <mesh filename="package://MELEW3_description/urdf/MELEW3_stl/hip_P.STL"/>
      </geometry>
    </visual>
    <collision>
      <geometry>
        <mesh filename="package://MELEW3_description/urdf/MELEW3_stl/hip_P.STL"/>
      </geometry>
    </collision> 
  </link>

  <link name="THIGH_R">
    <inertial>
      <mass value="1.2" />
      <origin xyz="0 0 -0.065" rpy="0 0 0" />
      <inertia ixx="0.00692" ixy="0.0" ixz="0.0" iyy="0.00692" iyz="0.0" izz="0.00032" />
    </inertial>
    <visual>
      <geometry>
        <mesh filename="package://MELEW3_description/urdf/MELEW3_stl/thigh.STL"/>
      </geometry>
    </visual>
    <collision>
      <geometry>
        <mesh filename="package://MELEW3_description/urdf/MELEW3_stl/thigh.STL"/>
      </geometry>
    </collision> 
  </link>

  <link name="KNEE_R">
    <inertial>
      <mass value="0.15" />
      <origin xyz="0 0 -0.15" rpy="0 0 0" />
      <inertia ixx="0.000035" ixy="0.0" ixz="0.0" iyy="0.00003" iyz="0.0" izz="0.000035" />
    </inertial>
    <visual>
      <geometry>
        <mesh filename="package://MELEW3_description/urdf/MELEW3_stl/knee.STL"/>
      </geometry>
    </visual>
    <collision>
      <geometry>
        <mesh filename="package://MELEW3_description/urdf/MELEW3_stl/knee.STL"/>
      </geometry>
    </collision> 
  </link>

  <link name="SHIN_R">
    <inertial>
      <mass value="0.6" />
      <origin xyz="0 0 -0.02" rpy="0 0 0" />
      <inertia ixx="0.00581125" ixy="0.0" ixz="0.0" iyy="0.00581125" iyz="0.0" izz="0.0000625" />
    </inertial>
    <visual>
      <geometry>
        <mesh filename="package://MELEW3_description/urdf/MELEW3_stl/shin.STL"/>
      </geometry>
    </visual>
    <collision>
      <geometry>
        <mesh filename="package://MELEW3_description/urdf/MELEW3_stl/shin.STL"/>
      </geometry>
    </collision> 
  </link>

  <link name="FOOT_R">
    <inertial>
      <mass value="0.05" />
      <origin xyz="0 0 -0.18" rpy="0 0 0" />
      <inertia ixx="0.000002" ixy="0.0" ixz="0.0" iyy="0.000002" iyz="0.0" izz="0.000002" />
    </inertial>
    <visual>
      <geometry>
        <mesh filename="package://MELEW3_description/urdf/MELEW3_stl/foot.STL"/>
      </geometry>
    </visual>
    <collision>
      <geometry>
        <mesh filename="package://MELEW3_description/urdf/MELEW3_stl/foot.STL"/>
      </geometry>
    </collision> 
  </link>


  <joint name="HIP_L" type="fixed">
    <origin xyz="0.0 0.125 0.0" rpy="0.0 0.0 0.0" />
    <parent link="BODY" />
    <child link="HIP_L" />
  </joint>

  <joint name="HIP_YAW_L" type="revolute">
    <origin xyz="0.0 0.0 0.0" rpy="0.0 0.0 0.0" />
    <axis xyz="0 0 1" />
    <parent link="HIP_L" />
    <child link="HIP_YAW_L" />
    <limit lower="-1.57079632679" upper="1.57079632679" effort="100.0" velocity="90.0" />
  </joint>

  <joint name="HIP_ROLL_L" type="revolute">
    <origin xyz="0.0 0.0 0.0" rpy="0.0 0.0 0.0" />
    <axis xyz="1 0 0" />
    <parent link="HIP_YAW_L" />
    <child link="HIP_ROLL_L" />
    <limit lower="-0.785398163397" upper="0.785398163397" effort="100.0" velocity="90.0" />
  </joint>

  <joint name="HIP_PITCH_L" type="revolute">
    <origin xyz="0.0 0.0 0.0" rpy="0.0 0.0 0.0" />
    <axis xyz="0 1 0" />
    <parent link="HIP_ROLL_L" />
    <child link="HIP_PITCH_L" />
    <limit lower="-1.57079632679" upper="1.57079632679" effort="100.0" velocity="90.0" />
  </joint>

  <joint name="THIGH_L" type="fixed">
    <origin xyz="0.0 0.0 -0.05" rpy="0.0 0.0 0.0" />
    <parent link="HIP_PITCH_L" />
    <child link="THIGH_L" />
  </joint>

  <joint name="KNEE_L" type="revolute">
    <origin xyz="0.0 0.0 -0.15" rpy="0.0 0.0 0.0" />
    <axis xyz="0 1 0" />
    <parent link="THIGH_L" />
    <child link="KNEE_L" />
    <limit lower="-2.35619449019" upper="-0.349065850399" effort="100.0" velocity="90.0" />
  </joint>
  
  <joint name="SHIN_L" type="fixed">
    <origin xyz="0.0 0.0 -0.02" rpy="0.0 0.0 0.0" />
    <parent link="KNEE_L" />
    <child link="SHIN_L" />
  </joint>

  <joint name="FOOT_L" type="fixed">
    <origin xyz="0.0 0.0 -0.18" rpy="0.0 0.0 0.0" />
    <parent link="SHIN_L" />
    <child link="FOOT_L" />
  </joint>

  <joint name="HIP_R" type="fixed">
    <origin xyz="0.0 -0.125 0.0" rpy="0.0 0.0 0.0" />
    <parent link="BODY" />
    <child link="HIP_R" />
  </joint>

  <joint name="HIP_YAW_R" type="revolute">
    <origin xyz="0.0 0.0 0.0" rpy="0.0 0.0 0.0" />
    <axis xyz="0 0 1" />
    <parent link="HIP_R" />
    <child link="HIP_YAW_R" />
    <limit lower="-1.57079632679" upper="1.57079632679" effort="100.0" velocity="90.0" />
  </joint>

  <joint name="HIP_ROLL_R" type="revolute">
    <origin xyz="0.0 0.0 0.0" rpy="0.0 0.0 0.0" />
    <axis xyz="1 0 0" />
    <parent link="HIP_YAW_R" />
    <child link="HIP_ROLL_R" />
    <limit lower="-0.785398163397" upper="0.785398163397" effort="100.0" velocity="90.0" />
  </joint>

  <joint name="HIP_PITCH_R" type="revolute">
    <origin xyz="0.0 0.0 0.0" rpy="0.0 0.0 0.0" />
    <axis xyz="0 1 0" />
    <parent link="HIP_ROLL_R" />
    <child link="HIP_PITCH_R" />
    <limit lower="-1.57079632679" upper="1.57079632679" effort="100.0" velocity="90.0" />
  </joint>

  <joint name="THIGH_R" type="fixed">
    <origin xyz="0.0 0.0 -0.05" rpy="0.0 0.0 0.0" />
    <parent link="HIP_PITCH_R" />
    <child link="THIGH_R" />
  </joint>

  <joint name="KNEE_R" type="revolute">
    <origin xyz="0.0 0.0 -0.15" rpy="0.0 0.0 0.0" />
    <axis xyz="0 1 0" />
    <parent link="THIGH_R" />
    <child link="KNEE_R" />
    <limit lower="-2.35619449019" upper="-0.349065850399" effort="100.0" velocity="90.0" />
  </joint>
  
  <joint name="SHIN_R" type="fixed">
    <origin xyz="0.0 0.0 -0.02" rpy="0.0 0.0 0.0" />
    <parent link="KNEE_R" />
    <child link="SHIN_R" />
  </joint>

  <joint name="FOOT_R" type="fixed">
    <origin xyz="0.0 0.0 -0.18" rpy="0.0 0.0 0.0" />
    <parent link="SHIN_R" />
    <child link="FOOT_R" />
  </joint>
</robot>