<?xml version="1.0"?>
<robot name="MELEW3" xmlns:xacro="http://ros.org/wiki/xacro">
  <xacro:include filename="$(find melew3_description)/xacro/utils.xacro"/>

  <link name="BODY">
    <inertial>
      <mass value="6.0" />
      <origin xyz="0 0 0" rpy="0 0 0" />
      <inertia ixx="0.08638450" ixy="0.0" ixz="0.0" iyy="0.13138450" iyz="0.0" izz="0.20500000" />
    </inertial>
    <visual>
      <geometry>
        <mesh filename="package://MELEW3_description/urdf/MELEW3_stl/body.STL"/>
      </geometry>
    </visual>
    <collision>
      <geometry>
        <mesh filename="package://MELEW3_description/urdf/MELEW3_stl/body.STL"/>
      </geometry>
    </collision>
  </link>

<!-- FL -->

  <link name="HIP_YAW_FL">
    <inertial>
      <mass value="0.05" />
      <origin xyz="0 0 0" rpy="0 0 0" />
      <inertia ixx="0.01" ixy="0.0" ixz="0.0" iyy="0.01" iyz="0.0" izz="0.01" />
    </inertial>
    <visual>
      <geometry>
        <mesh filename="package://MELEW3_description/urdf/MELEW3_stl/joint_y.STL"/>
      </geometry>
    </visual>
    <collision>
      <geometry>
        <mesh filename="package://MELEW3_description/urdf/MELEW3_stl/joint_y.STL"/>
      </geometry>
    </collision>  
  </link>

  <link name="HIP_ROLL_FL">
    <inertial>
      <mass value="0.05" />
      <origin xyz="0 0 0" rpy="0 0 0" />
      <inertia ixx="0.01" ixy="0.0" ixz="0.0" iyy="0.01" iyz="0.0" izz="0.01" />
    </inertial>
    <visual>
      <geometry>
        <mesh filename="package://MELEW3_description/urdf/MELEW3_stl/joint_r.STL"/>
      </geometry>
    </visual>
    <collision>
      <geometry>
        <mesh filename="package://MELEW3_description/urdf/MELEW3_stl/joint_r.STL"/>
      </geometry>
    </collision>  
  </link>

  <link name="HIP_PITCH_FL">
    <inertial>
      <mass value="4.0" />
      <origin xyz="0 0 -0.1" rpy="0 0 0" />
      <inertia ixx="0.06000329" ixy="0.0" ixz="0.0" iyy="0.06024268" iyz="0.0" izz="0.01" />
    </inertial>
    <visual>
      <geometry>
        <mesh filename="package://MELEW3_description/urdf/MELEW3_stl/link_small.STL"/>
      </geometry>
    </visual>
    <collision>
      <geometry>
        <mesh filename="package://MELEW3_description/urdf/MELEW3_stl/link_small.STL"/>
      </geometry>
    </collision> 
  </link>

  <link name="KNEE_FL">
    <inertial>
      <mass value="1.0" />
      <origin xyz="0 0 -0.1" rpy="0 0 0" />
      <inertia ixx="0.01500082" ixy="0.0" ixz="0.0" iyy="0.01506067" iyz="0.0" izz="0.01" />
    </inertial>
    <visual>
      <geometry>
        <mesh filename="package://MELEW3_description/urdf/MELEW3_stl/link_small.STL"/>
      </geometry>
    </visual>
    <collision>
      <geometry>
        <mesh filename="package://MELEW3_description/urdf/MELEW3_stl/link_small.STL"/>
      </geometry>
    </collision> 
  </link>

<!-- FR -->

<link name="HIP_YAW_FR">
    <inertial>
      <mass value="0.05" />
      <origin xyz="0 0 0" rpy="0 0 0" />
      <inertia ixx="0.01" ixy="0.0" ixz="0.0" iyy="0.01" iyz="0.0" izz="0.01" />
    </inertial>
    <visual>
      <geometry>
        <mesh filename="package://MELEW3_description/urdf/MELEW3_stl/joint_y.STL"/>
      </geometry>
    </visual>
    <collision>
      <geometry>
        <mesh filename="package://MELEW3_description/urdf/MELEW3_stl/joint_y.STL"/>
      </geometry>
    </collision>  
  </link>

  <link name="HIP_ROLL_FR">
    <inertial>
      <mass value="0.05" />
      <origin xyz="0 0 0" rpy="0 0 0" />
      <inertia ixx="0.01" ixy="0.0" ixz="0.0" iyy="0.01" iyz="0.0" izz="0.01" />
    </inertial>
    <visual>
      <geometry>
        <mesh filename="package://MELEW3_description/urdf/MELEW3_stl/joint_r.STL"/>
      </geometry>
    </visual>
    <collision>
      <geometry>
        <mesh filename="package://MELEW3_description/urdf/MELEW3_stl/joint_r.STL"/>
      </geometry>
    </collision>  
  </link>

  <link name="HIP_PITCH_FR">
    <inertial>
      <mass value="1.0" />
      <origin xyz="0 0 -0.1" rpy="0 0 0" />
      <inertia ixx="0.06000329" ixy="0.0" ixz="0.0" iyy="0.06024268" iyz="0.0" izz="0.01" />
    </inertial>
    <visual>
      <geometry>
        <mesh filename="package://MELEW3_description/urdf/MELEW3_stl/link_small.STL"/>
      </geometry>
    </visual>
    <collision>
      <geometry>
        <mesh filename="package://MELEW3_description/urdf/MELEW3_stl/link_small.STL"/>
      </geometry>
    </collision> 
  </link>

  <link name="KNEE_FR">
    <inertial>
      <mass value="1.0" />
      <origin xyz="0 0 -0.1" rpy="0 0 0" />
      <inertia ixx="0.01500082" ixy="0.0" ixz="0.0" iyy="0.01506067" iyz="0.0" izz="0.01" />
    </inertial>
    <visual>
      <geometry>
        <mesh filename="package://MELEW3_description/urdf/MELEW3_stl/link_small.STL"/>
      </geometry>
    </visual>
    <collision>
      <geometry>
        <mesh filename="package://MELEW3_description/urdf/MELEW3_stl/link_small.STL"/>
      </geometry>
    </collision> 
  </link>

<!-- BL -->

<link name="HIP_YAW_BL">
    <inertial>
      <mass value="0.05" />
      <origin xyz="0 0 0" rpy="0 0 0" />
      <inertia ixx="0.01" ixy="0.0" ixz="0.0" iyy="0.01" iyz="0.0" izz="0.01" />
    </inertial>
    <visual>
      <geometry>
        <mesh filename="package://MELEW3_description/urdf/MELEW3_stl/joint_y.STL"/>
      </geometry>
    </visual>
    <collision>
      <geometry>
        <mesh filename="package://MELEW3_description/urdf/MELEW3_stl/joint_y.STL"/>
      </geometry>
    </collision>  
  </link>

  <link name="HIP_ROLL_BL">
    <inertial>
      <mass value="0.05" />
      <origin xyz="0 0 0" rpy="0 0 0" />
      <inertia ixx="0.01" ixy="0.0" ixz="0.0" iyy="0.01" iyz="0.0" izz="0.01" />
    </inertial>
    <visual>
      <geometry>
        <mesh filename="package://MELEW3_description/urdf/MELEW3_stl/joint_r.STL"/>
      </geometry>
    </visual>
    <collision>
      <geometry>
        <mesh filename="package://MELEW3_description/urdf/MELEW3_stl/joint_r.STL"/>
      </geometry>
    </collision>  
  </link>

  <link name="HIP_PITCH_BL">
    <inertial>
      <mass value="1.0" />
      <origin xyz="0 0 -0.1" rpy="0 0 0" />
      <inertia ixx="0.06000329" ixy="0.0" ixz="0.0" iyy="0.06024268" iyz="0.0" izz="0.01" />
    </inertial>
    <visual>
      <geometry>
        <mesh filename="package://MELEW3_description/urdf/MELEW3_stl/link_small.STL"/>
      </geometry>
    </visual>
    <collision>
      <geometry>
        <mesh filename="package://MELEW3_description/urdf/MELEW3_stl/link_small.STL"/>
      </geometry>
    </collision> 
  </link>

  <link name="KNEE_BL">
    <inertial>
      <mass value="1.0" />
      <origin xyz="0 0 -0.1" rpy="0 0 0" />
      <inertia ixx="0.01500082" ixy="0.0" ixz="0.0" iyy="0.01506067" iyz="0.0" izz="0.01" />
    </inertial>
    <visual>
      <geometry>
        <mesh filename="package://MELEW3_description/urdf/MELEW3_stl/link_small.STL"/>
      </geometry>
    </visual>
    <collision>
      <geometry>
        <mesh filename="package://MELEW3_description/urdf/MELEW3_stl/link_small.STL"/>
      </geometry>
    </collision> 
  </link>

<!-- BR -->

<link name="HIP_YAW_BR">
    <inertial>
      <mass value="0.05" />
      <origin xyz="0 0 0" rpy="0 0 0" />
      <inertia ixx="0.01" ixy="0.0" ixz="0.0" iyy="0.01" iyz="0.0" izz="0.01" />
    </inertial>
    <visual>
      <geometry>
        <mesh filename="package://MELEW3_description/urdf/MELEW3_stl/joint_y.STL"/>
      </geometry>
    </visual>
    <collision>
      <geometry>
        <mesh filename="package://MELEW3_description/urdf/MELEW3_stl/joint_y.STL"/>
      </geometry>
    </collision>  
  </link>

  <link name="HIP_ROLL_BR">
    <inertial>
      <mass value="0.05" />
      <origin xyz="0 0 0" rpy="0 0 0" />
      <inertia ixx="0.01" ixy="0.0" ixz="0.0" iyy="0.01" iyz="0.0" izz="0.01" />
    </inertial>
    <visual>
      <geometry>
        <mesh filename="package://MELEW3_description/urdf/MELEW3_stl/joint_r.STL"/>
      </geometry>
    </visual>
    <collision>
      <geometry>
        <mesh filename="package://MELEW3_description/urdf/MELEW3_stl/joint_r.STL"/>
      </geometry>
    </collision>  
  </link>

  <link name="HIP_PITCH_BR">
    <inertial>
      <mass value="1.0" />
      <origin xyz="0 0 -0.1" rpy="0 0 0" />
      <inertia ixx="0.06000329" ixy="0.0" ixz="0.0" iyy="0.06024268" iyz="0.0" izz="0.01" />
    </inertial>
    <visual>
      <geometry>
        <mesh filename="package://MELEW3_description/urdf/MELEW3_stl/link_small.STL"/>
      </geometry>
    </visual>
    <collision>
      <geometry>
        <mesh filename="package://MELEW3_description/urdf/MELEW3_stl/link_small.STL"/>
      </geometry>
    </collision> 
  </link>

  <link name="KNEE_BR">
    <inertial>
      <mass value="1.0" />
      <origin xyz="0 0 -0.1" rpy="0 0 0" />
      <inertia ixx="0.01" ixy="0.0" ixz="0.0" iyy="0.01" iyz="0.0" izz="0.01" />
    </inertial>
    <visual>
      <geometry>
        <mesh filename="package://MELEW3_description/urdf/MELEW3_stl/link_small.STL"/>
      </geometry>
    </visual>
    <collision>
      <geometry>
        <mesh filename="package://MELEW3_description/urdf/MELEW3_stl/link_small.STL"/>
      </geometry>
    </collision> 
  </link>

<!-- WHEEL -->

<link name="WHEEL_FL">
    <inertial>
      <mass value="1.0" />
      <origin xyz="0 0 0" rpy="0 0 0" />
      <inertia ixx="0.01" ixy="0.0" ixz="0.0" iyy="0.01" iyz="0.0" izz="0.01" />
    </inertial>
    <visual>
      <geometry>
        <mesh filename="package://MELEW3_description/urdf/MELEW3_stl/wheel.STL"/>
      </geometry>
    </visual>
    <collision>
      <geometry>
        <mesh filename="package://MELEW3_description/urdf/MELEW3_stl/wheel.STL"/>
      </geometry>
    </collision> 
  </link>

  <link name="WHEEL_FR">
    <inertial>
      <mass value="1.0" />
      <origin xyz="0 0 0" rpy="0 0 0" />
      <inertia ixx="0.01" ixy="0.0" ixz="0.0" iyy="0.01" iyz="0.0" izz="0.01" />
    </inertial>
    <visual>
      <geometry>
        <mesh filename="package://MELEW3_description/urdf/MELEW3_stl/wheel.STL"/>
      </geometry>
    </visual>
    <collision>
      <geometry>
        <mesh filename="package://MELEW3_description/urdf/MELEW3_stl/wheel.STL"/>
      </geometry>
    </collision> 
  </link>

  <link name="WHEEL_BL">
    <inertial>
      <mass value="1.0" />
      <origin xyz="0 0 0" rpy="0 0 0" />
      <inertia ixx="0.01" ixy="0.0" ixz="0.0" iyy="0.01" iyz="0.0" izz="0.01" />
    </inertial>
    <visual>
      <geometry>
        <mesh filename="package://MELEW3_description/urdf/MELEW3_stl/wheel.STL"/>
      </geometry>
    </visual>
    <collision>
      <geometry>
        <mesh filename="package://MELEW3_description/urdf/MELEW3_stl/wheel.STL"/>
      </geometry>
    </collision> 
  </link>

  <link name="WHEEL_BR">
    <inertial>
      <mass value="1.0" />
      <origin xyz="0 0 0" rpy="0 0 0" />
      <inertia ixx="0.01" ixy="0.0" ixz="0.0" iyy="0.01" iyz="0.0" izz="0.01" />
    </inertial>
    <visual>
      <geometry>
        <mesh filename="package://MELEW3_description/urdf/MELEW3_stl/wheel.STL"/>
      </geometry>
    </visual>
    <collision>
      <geometry>
        <mesh filename="package://MELEW3_description/urdf/MELEW3_stl/wheel.STL"/>
      </geometry>
    </collision> 
  </link>

<!-- \\\\\\\\\\\\\\\\\\\\\\\\\\\\\\\\\\\\\\\\\\\\\\\\\\\\\\\\\\\\\\\\\\\\\\\\\\\\\\\\ -->

<!-- FL -->

  <joint name="HIP_YAW_FL" type="revolute">
    <origin xyz="0.2 0.15 0.0" rpy="0.0 0.0 0.0" />
    <axis xyz="0 0 1" />
    <parent link="BODY" />
    <child link="HIP_YAW_FL" />
    <limit lower="-1.57079632679" upper="1.57079632679" effort="100.0" velocity="90.0" />
  </joint>

  <joint name="HIP_ROLL_FL" type="revolute">
    <origin xyz="0.0 0.0 0.0" rpy="0.0 0.0 0.0" />
    <axis xyz="1 0 0" />
    <parent link="HIP_YAW_FL" />
    <child link="HIP_ROLL_FL" />
    <limit lower="-0.785398163397" upper="0.785398163397" effort="100.0" velocity="90.0" />
  </joint>

  <joint name="HIP_PITCH_FL" type="revolute">
    <origin xyz="0.0 0.0 0.0" rpy="0.0 0.0 0.0" />
    <axis xyz="0 1 0" />
    <parent link="HIP_ROLL_FL" />
    <child link="HIP_PITCH_FL" />
    <limit lower="-1.57079632679" upper="1.57079632679" effort="100.0" velocity="90.0" />
  </joint>

  <joint name="KNEE_FL" type="revolute">
    <origin xyz="0.0 0.0 -0.2" rpy="0.0 0.0 0.0" />
    <axis xyz="0 1 0" />
    <parent link="HIP_PITCH_FL" />
    <child link="KNEE_FL" />
    <limit lower="-2.35619449019" upper="0.0" effort="100.0" velocity="90.0" />
  </joint>

  <joint name="WHEEL_FL" type="continuous">
    <origin xyz="0.0 0.0 -0.2" rpy="0.0 0.0 0.0" />
    <axis xyz="0 1 0" />
    <parent link="KNEE_FL" />
    <child link="WHEEL_FL"/>
    <limit effort="100.0" velocity="90.0" />
  </joint>

<!-- FR -->

  <joint name="HIP_YAW_FR" type="revolute">
    <origin xyz="0.2 -0.15 0.0" rpy="0.0 0.0 0.0" />
    <axis xyz="0 0 1" />
    <parent link="BODY" />
    <child link="HIP_YAW_FR" />
    <limit lower="-1.57079632679" upper="1.57079632679" effort="100.0" velocity="90.0" />
  </joint>

  <joint name="HIP_ROLL_FR" type="revolute">
    <origin xyz="0.0 0.0 0.0" rpy="0.0 0.0 0.0" />
    <axis xyz="1 0 0" />
    <parent link="HIP_YAW_FR" />
    <child link="HIP_ROLL_FR" />
    <limit lower="-0.785398163397" upper="0.785398163397" effort="100.0" velocity="90.0" />
  </joint>

  <joint name="HIP_PITCH_FR" type="revolute">
    <origin xyz="0.0 0.0 0.0" rpy="0.0 0.0 0.0" />
    <axis xyz="0 1 0" />
    <parent link="HIP_ROLL_FR" />
    <child link="HIP_PITCH_FR" />
    <limit lower="-1.57079632679" upper="1.57079632679" effort="100.0" velocity="90.0" />
  </joint>

  <joint name="KNEE_FR" type="revolute">
    <origin xyz="0.0 0.0 -0.2" rpy="0.0 0.0 0.0" />
    <axis xyz="0 1 0" />
    <parent link="HIP_PITCH_FR" />
    <child link="KNEE_FR" />
    <limit lower="-2.35619449019" upper="0.0" effort="100.0" velocity="90.0" />
  </joint>

  <joint name="WHEEL_FR" type="continuous">
    <origin xyz="0.0 0.0 -0.2" rpy="0.0 0.0 0.0" />
    <axis xyz="0 1 0" />
    <parent link="KNEE_FR" />
    <child link="WHEEL_FR"/>
    <limit effort="100.0" velocity="90.0" />
  </joint>

<!-- BL -->

  <joint name="HIP_YAW_BL" type="revolute">
    <origin xyz="-0.2 0.15 0.0" rpy="0.0 0.0 0.0" />
    <axis xyz="0 0 1" />
    <parent link="BODY" />
    <child link="HIP_YAW_BL" />
    <limit lower="-1.57079632679" upper="1.57079632679" effort="100.0" velocity="90.0" />
  </joint>

  <joint name="HIP_ROLL_BL" type="revolute">
    <origin xyz="0.0 0.0 0.0" rpy="0.0 0.0 0.0" />
    <axis xyz="1 0 0" />
    <parent link="HIP_YAW_BL" />
    <child link="HIP_ROLL_BL" />
    <limit lower="-0.785398163397" upper="0.785398163397" effort="100.0" velocity="90.0" />
  </joint>

  <joint name="HIP_PITCH_BL" type="revolute">
    <origin xyz="0.0 0.0 0.0" rpy="0.0 0.0 0.0" />
    <axis xyz="0 1 0" />
    <parent link="HIP_ROLL_BL" />
    <child link="HIP_PITCH_BL" />
    <limit lower="-1.57079632679" upper="1.57079632679" effort="100.0" velocity="90.0" />
  </joint>

  <joint name="KNEE_BL" type="revolute">
    <origin xyz="0.0 0.0 -0.2" rpy="0.0 0.0 0.0" />
    <axis xyz="0 1 0" />
    <parent link="HIP_PITCH_BL" />
    <child link="KNEE_BL" />
    <limit lower="0.0" upper="2.35619449019" effort="100.0" velocity="90.0" />
  </joint>

  <joint name="WHEEL_BL" type="continuous">
    <origin xyz="0.0 0.0 -0.2" rpy="0.0 0.0 0.0" />
    <axis xyz="0 1 0" />
    <parent link="KNEE_BL" />
    <child link="WHEEL_BL"/>
    <limit effort="100.0" velocity="90.0" />
  </joint>

<!-- BR -->

  <joint name="HIP_YAW_BR" type="revolute">
    <origin xyz="-0.2 -0.15 0.0" rpy="0.0 0.0 0.0" />
    <axis xyz="0 0 1" />
    <parent link="BODY" />
    <child link="HIP_YAW_BR" />
    <limit lower="-1.57079632679" upper="1.57079632679" effort="100.0" velocity="90.0" />
  </joint>

  <joint name="HIP_ROLL_BR" type="revolute">
    <origin xyz="0.0 0.0 0.0" rpy="0.0 0.0 0.0" />
    <axis xyz="1 0 0" />
    <parent link="HIP_YAW_BR" />
    <child link="HIP_ROLL_BR" />
    <limit lower="-0.785398163397" upper="0.785398163397" effort="100.0" velocity="90.0" />
  </joint>

  <joint name="HIP_PITCH_BR" type="revolute">
    <origin xyz="0.0 0.0 0.0" rpy="0.0 0.0 0.0" />
    <axis xyz="0 1 0" />
    <parent link="HIP_ROLL_BR" />
    <child link="HIP_PITCH_BR" />
    <limit lower="-1.57079632679" upper="1.57079632679" effort="100.0" velocity="90.0" />
  </joint>

  <joint name="KNEE_BR" type="revolute">
    <origin xyz="0.0 0.0 -0.2" rpy="0.0 0.0 0.0" />
    <axis xyz="0 1 0" />
    <parent link="HIP_PITCH_BR" />
    <child link="KNEE_BR" />
    <limit lower="0.0" upper="2.35619449019" effort="100.0" velocity="90.0" />
  </joint>

  <joint name="WHEEL_BR" type="continuous">
    <origin xyz="0.0 0.0 -0.2" rpy="0.0 0.0 0.0" />
    <axis xyz="0 1 0" />
    <parent link="KNEE_BR" />
    <child link="WHEEL_BR"/>
    <limit effort="100.0" velocity="90.0" />
  </joint>

  <xacro:joint_effort_trans_v0 name="HIP_YAW_FL"/>
  <xacro:joint_effort_trans_v0 name="HIP_ROLL_FL"/>
  <xacro:joint_effort_trans_v0 name="HIP_PITCH_FL"/>
  <xacro:joint_effort_trans_v0 name="KNEE_FL"/>
  <xacro:joint_effort_trans_v0 name="HIP_YAW_FR"/>
  <xacro:joint_effort_trans_v0 name="HIP_ROLL_FR"/>
  <xacro:joint_effort_trans_v0 name="HIP_PITCH_FR"/>
  <xacro:joint_effort_trans_v0 name="KNEE_FR"/>
  <xacro:joint_effort_trans_v0 name="HIP_YAW_BL"/>
  <xacro:joint_effort_trans_v0 name="HIP_ROLL_BL"/>
  <xacro:joint_effort_trans_v0 name="HIP_PITCH_BL"/>
  <xacro:joint_effort_trans_v0 name="KNEE_BL"/>
  <xacro:joint_effort_trans_v0 name="HIP_YAW_BR"/>
  <xacro:joint_effort_trans_v0 name="HIP_ROLL_BR"/>
  <xacro:joint_effort_trans_v0 name="HIP_PITCH_BR"/>
  <xacro:joint_effort_trans_v0 name="KNEE_BR"/>
  <xacro:joint_effort_trans_v0 name="WHEEL_FL"/>
  <xacro:joint_effort_trans_v0 name="WHEEL_FR"/>
  <xacro:joint_effort_trans_v0 name="WHEEL_BL"/>
  <xacro:joint_effort_trans_v0 name="WHEEL_BR"/>

</robot>